Workbook

Sheet README
A1: WSN Clustering Protocols — Comparison Workbook
A2: Energy-Efficient Secure Clustering in WSNs Using Hybrid Cryptography — Eng. Rahma Khaled Oshba
A4: How to read this workbook
A5: Dashboard | B5: Headline results and charts: the best configuration of every protocol family side by side.
A6: Unified Comparison | B6: Every protocol and every proposed version in the SAME environment (100 nodes, 100×100 m, BS center). Ranks and deltas are formulas.
A7: Reproduction | B7: Published paper numbers vs. our paper-exact reproduction vs. the unified environment, with gaps as formulas.
A8: Proposed Evolution | B8: v1 → v8-Chain, one mechanism change per version; Δ vs. previous version and vs. v1 are formulas.
A9: Center vs Far BS | B9: The same protocol with the BS at the field center (50,50) and far away (50,−100).
A10: v8 Analysis | B10: Leave-one-out ablation, CH routing-mode comparison and 8-topology robustness of the final protocol.
A12: Conventions
A13: Red header | B13: Simulation output (entered values).
A14: Charcoal header | B14: Calculated column (formula) — do not type over it.
A15: Pink row | B15: Final proposed protocol (v8 / v8-Chain).
A16: FND / HND / LND | B16: Round in which the first / half / last node died (higher is better).
A17: PDR | B17: Packets delivered to the BS ÷ packets generated over the whole lifetime.
A19: Simulation environment
A20: Network size | B20: 100 nodes
A21: Field | B21: 100 × 100 m
A22: Initial energy E0 | B22: 0.5 J / node
A23: Packet size | B23: 2000 bits (control 200 bits)
A24: Data rate | B24: 250 kbps
A25: BS position | B25: (50, 50) center; far scenario (50, −100)
A26: Communication range | B26: 25 m
A27: Radio model | B27: First-order, two-slope (d² / d⁴)
A28: E_elec | B28: 50 nJ/bit
A29: E_fs | B29: 10 pJ/bit/m²
A30: E_mp | B30: 0.0013 pJ/bit/m⁴
A31: E_DA | B31: 5 nJ/bit/signal
... A34: Simulator | B34: ns-3.41, C++ (analytical energy model)
A36: References
A37: [1] | B37: W. R. Heinzelman, A. Chandrakasan and H. Balakrishnan, “Energy-Efficient Communication Protocol for Wireless Microsensor Networks,” Proc. HICSS, 2000.
A38: [2] | B38: O. Younis and S. Fahmy, “HEED: A Hybrid, Energy-Efficient, Distributed Clustering Approach for Ad Hoc Sensor Networks,” IEEE Trans. Mobile Computing, 2004.
A39: [3] | B39: S. Lindsey and C. S. Raghavendra, “PEGASIS: Power-Efficient Gathering in Sensor Information Systems,” Proc. IEEE Aerospace Conference, 2002.
A40: [4] | B40: Shrestha, Kim, Jung and Lee, “The Improved Energy Efficient LEACH Protocol Technology of WSNs,” IJIBC, 2015.
A41: [5] | B41: A. Razaque, M. Mudigulam, K. Gavini, F. Amsaad, M. Abdulgader and P. Krishna, “H-LEACH: Hybrid-Low Energy Adaptive Clustering Hierarchy for Wireless Sensor Networks,” Proc. IEEE LISAT, 2016.
A42: [6] | B42: Kaur, Kour and Singh, “EECH-HEED: An Adaptive Hybrid Clustering Protocol for Energy Efficient Soil Monitoring,” Scientific Reports, 2025.
A43: [7] | B43: Subedi, Acharya, Lee and Lee, “Two-Level Clustering Algorithm for Cluster Head Selection in Randomly Deployed WSNs,” Telecom (MDPI), 2024.
A44: [8] | B44: Juwaied and Jackowska-Strumillo, “DL-HEED: A Deep Learning Approach to Energy-Efficient Clustering in Heterogeneous WSNs,” Applied Sciences (MDPI), 2025.
A45: [9] | B45: El-Sayed, Abd-Elgaber and Refaay, “An Intelligent RL Enhanced Improved LEACH Protocol for Prolonging WSN Lifetime,” Scientific Reports, 2026.
A46: [10] | B46: J. Jassbi and S. Moridi, “Fault Tolerance and Energy Efficient Clustering Algorithm in Wireless Sensor Networks: FTEC,” Wireless Personal Communications, 2019. doi:10.1007/s11277-019-06281-6
...

Sheet Dashboard
A1: Dashboard — best configuration of each family (BS center)
A2: Values are pulled from "Unified Comparison" with INDEX/MATCH, so they update if that sheet changes.
A4: Protocol | B4: Stage | C4: FND | D4: HND | E4: LND | F4: PDR
A5: LEACH | B5: Edited | C5: =INDEX('Unified Comparison'!$E$5:$E$28,MATCH(1,INDEX(('Unified Comparison'!$B$5:$B$28=A5)*('Unified Comparison'!$C$5:$C$28=B5),0),0)) -> 1383 | D5: =INDEX('Unified Comparison'!$F$5:$F$28,MATCH(1,INDEX(('Unified Comparison'!$B$5:$B$28=A5)*('Unified Comparison'!$C$5:$C$28=B5),0),0)) -> 1586 | E5: =INDEX('Unified Comparison'!$G$5:$G$28,MATCH(1,INDEX(('Unified Comparison'!$B$5:$B$28=A5)*('Unified Comparison'!$C$5:$C$28=B5),0),0)) -> 1842 | F5: =INDEX('Unified Comparison'!$H$5:$H$28,MATCH(1,INDEX(('Unified Comparison'!$B$5:$B$28=A5)*('Unified Comparison'!$C$5:$C$28=B5),0),0)) -> 0.994
A6: HEED | B6: Edited | C6: =INDEX('Unified Comparison'!$E$5:$E$28,MATCH(1,INDEX(('Unified Comparison'!$B$5:$B$28=A6)*('Unified Comparison'!$C$5:$C$28=B6),0),0)) -> 634 | D6: =INDEX('Unified Comparison'!$F$5:$F$28,MATCH(1,INDEX(('Unified Comparison'!$B$5:$B$28=A6)*('Unified Comparison'!$C$5:$C$28=B6),0),0)) -> 1216 | E6: =INDEX('Unified Comparison'!$G$5:$G$28,MATCH(1,INDEX(('Unified Comparison'!$B$5:$B$28=A6)*('Unified Comparison'!$C$5:$C$28=B6),0),0)) -> 1883 | F6: =INDEX('Unified Comparison'!$H$5:$H$28,MATCH(1,INDEX(('Unified Comparison'!$B$5:$B$28=A6)*('Unified Comparison'!$C$5:$C$28=B6),0),0)) -> 0.9968
A7: PEGASIS | B7: Edited | C7: =INDEX('Unified Comparison'!$E$5:$E$28,MATCH(1,INDEX(('Unified Comparison'!$B$5:$B$28=A7)*('Unified Comparison'!$C$5:$C$28=B7),0),0)) -> 1324 | D7: =INDEX('Unified Comparison'!$F$5:$F$28,MATCH(1,INDEX(('Unified Comparison'!$B$5:$B$28=A7)*('Unified Comparison'!$C$5:$C$28=B7),0),0)) -> 2352 | E7: =INDEX('Unified Comparison'!$G$5:$G$28,MATCH(1,INDEX(('Unified Comparison'!$B$5:$B$28=A7)*('Unified Comparison'!$C$5:$C$28=B7),0),0)) -> 3504 | F7: =INDEX('Unified Comparison'!$H$5:$H$28,MATCH(1,INDEX(('Unified Comparison'!$B$5:$B$28=A7)*('Unified Comparison'!$C$5:$C$28=B7),0),0)) -> 0.9942
A8: SH-LEACH | B8: Improved | C8: =INDEX('Unified Comparison'!$E$5:$E$28,MATCH(1,INDEX(('Unified Comparison'!$B$5:$B$28=A8)*('Unified Comparison'!$C$5:$C$28=B8),0),0)) -> 1247 | D8: =INDEX('Unified Comparison'!$F$5:$F$28,MATCH(1,INDEX(('Unified Comparison'!$B$5:$B$28=A8)*('Unified Comparison'!$C$5:$C$28=B8),0),0)) -> 1600 | E8: =INDEX('Unified Comparison'!$G$5:$G$28,MATCH(1,INDEX(('Unified Comparison'!$B$5:$B$28=A8)*('Unified Comparison'!$C$5:$C$28=B8),0),0)) -> 1649 | F8: =INDEX('Unified Comparison'!$H$5:$H$28,MATCH(1,INDEX(('Unified Comparison'!$B$5:$B$28=A8)*('Unified Comparison'!$C$5:$C$28=B8),0),0)) -> 0.9979
A9: H-LEACH | B9: Improved | C9: =INDEX('Unified Comparison'!$E$5:$E$28,MATCH(1,INDEX(('Unified Comparison'!$B$5:$B$28=A9)*('Unified Comparison'!$C$5:$C$28=B9),0),0)) -> 2347 | D9: =INDEX('Unified Comparison'!$F$5:$F$28,MATCH(1,INDEX(('Unified Comparison'!$B$5:$B$28=A9)*('Unified Comparison'!$C$5:$C$28=B9),0),0)) -> 2449 | E9: =INDEX('Unified Comparison'!$G$5:$G$28,MATCH(1,INDEX(('Unified Comparison'!$B$5:$B$28=A9)*('Unified Comparison'!$C$5:$C$28=B9),0),0)) -> 2499 | F9: =INDEX('Unified Comparison'!$H$5:$H$28,MATCH(1,INDEX(('Unified Comparison'!$B$5:$B$28=A9)*('Unified Comparison'!$C$5:$C$28=B9),0),0)) -> 0.9733
A10: v3 | B10: Proposed | C10: =INDEX('Unified Comparison'!$E$5:$E$28,MATCH(1,INDEX(('Unified Comparison'!$B$5:$B$28=A10)*('Unified Comparison'!$C$5:$C$28=B10),0),0)) -> 1730 | D10: =INDEX('Unified Comparison'!$F$5:$F$28,MATCH(1,INDEX(('Unified Comparison'!$B$5:$B$28=A10)*('Unified Comparison'!$C$5:$C$28=B10),0),0)) -> 2081 | E10: =INDEX('Unified Comparison'!$G$5:$G$28,MATCH(1,INDEX(('Unified Comparison'!$B$5:$B$28=A10)*('Unified Comparison'!$C$5:$C$28=B10),0),0)) -> 2703 | F10: =INDEX('Unified Comparison'!$H$5:$H$28,MATCH(1,INDEX(('Unified Comparison'!$B$5:$B$28=A10)*('Unified Comparison'!$C$5:$C$28=B10),0),0)) -> 0.9772
A11: v7 (Center) | B11: Proposed | C11: =INDEX('Unified Comparison'!$E$5:$E$28,MATCH(1,INDEX(('Unified Comparison'!$B$5:$B$28=A11)*('Unified Comparison'!$C$5:$C$28=B11),0),0)) -> 1551 | D11: =INDEX('Unified Comparison'!$F$5:$F$28,MATCH(1,INDEX(('Unified Comparison'!$B$5:$B$28=A11)*('Unified Comparison'!$C$5:$C$28=B11),0),0)) -> 1976 | E11: =INDEX('Unified Comparison'!$G$5:$G$28,MATCH(1,INDEX(('Unified Comparison'!$B$5:$B$28=A11)*('Unified Comparison'!$C$5:$C$28=B11),0),0)) -> 2066 | F11: =INDEX('Unified Comparison'!$H$5:$H$28,MATCH(1,INDEX(('Unified Comparison'!$B$5:$B$28=A11)*('Unified Comparison'!$C$5:$C$28=B11),0),0)) -> 0.98432
A12: v7.1 Multihop (Int 5) | B12: Proposed | C12: =INDEX('Unified Comparison'!$E$5:$E$28,MATCH(1,INDEX(('Unified Comparison'!$B$5:$B$28=A12)*('Unified Comparison'!$C$5:$C$28=B12),0),0)) -> 1491 | D12: =INDEX('Unified Comparison'!$F$5:$F$28,MATCH(1,INDEX(('Unified Comparison'!$B$5:$B$28=A12)*('Unified Comparison'!$C$5:$C$28=B12),0),0)) -> 1991 | E12: =INDEX('Unified Comparison'!$G$5:$G$28,MATCH(1,INDEX(('Unified Comparison'!$B$5:$B$28=A12)*('Unified Comparison'!$C$5:$C$28=B12),0),0)) -> 2086 | F12: =INDEX('Unified Comparison'!$H$5:$H$28,MATCH(1,INDEX(('Unified Comparison'!$B$5:$B$28=A12)*('Unified Comparison'!$C$5:$C$28=B12),0),0)) -> 0.9849
A13: v8-Chain (Center) | B13: Proposed | C13: =INDEX('Unified Comparison'!$E$5:$E$28,MATCH(1,INDEX(('Unified Comparison'!$B$5:$B$28=A13)*('Unified Comparison'!$C$5:$C$28=B13),0),0)) -> 2621 | D13: =INDEX('Unified Comparison'!$F$5:$F$28,MATCH(1,INDEX(('Unified Comparison'!$B$5:$B$28=A13)*('Unified Comparison'!$C$5:$C$28=B13),0),0)) -> 2711 | E13: =INDEX('Unified Comparison'!$G$5:$G$28,MATCH(1,INDEX(('Unified Comparison'!$B$5:$B$28=A13)*('Unified Comparison'!$C$5:$C$28=B13),0),0)) -> 2756 | F13: =INDEX('Unified Comparison'!$H$5:$H$28,MATCH(1,INDEX(('Unified Comparison'!$B$5:$B$28=A13)*('Unified Comparison'!$C$5:$C$28=B13),0),0)) -> 0.992668
A15: Headline
A16: v8-Chain FND vs best literature hybrid (H-LEACH Improved) | C16: =C13/C9-1 -> 0.11674478
A17: v8-Chain FND vs LEACH | C17: =C13/C5-1 -> 0.89515546
A18: v8-Chain PDR vs v7 (Center) | C18: =(F13-F11)*100 -> 0.8348
A19: v8-Chain Far-BS FND vs v7 Far-BS | C19: ='Center vs Far BS'!F9/'Center vs Far BS'!F7-1 -> 0.35545024

Sheet Unified Comparison
A1: Unified-environment comparison (BS at field center)
A2: All rows: 100 nodes, 100×100 m, E0 = 0.5 J, 2000-bit packets, two-slope radio, seed 12345. Rank 1 = best.
A4: Family | B4: Protocol / Version | C4: Stage | D4: Mechanism | E4: FND | F4: HND | G4: LND | H4: PDR | I4: LND vs LEACH | J4: FND ÷ LND (balance) | K4: Rank LND | L4: Rank PDR
A5: Baseline | B5: LEACH | C5: Edited | D5: Randomised CH rotation | E5: 1383 | F5: 1586 | G5: 1842 | H5: 0.994 | I5: =G5/$G$5-1 -> 0 | J5: =E5/G5 -> 0.75081433 | K5: =RANK(G5,$G$5:$G$28) -> 20 | L5: =RANK(H5,$H$5:$H$28) -> 7
A6: Baseline | B6: HEED | C6: Edited | D6: Iterative energy + cost CH negotiation | E6: 634 | F6: 1216 | G6: 1883 | H6: 0.9968 | I6: =G6/$G$5-1 -> 0.022258415 | J6: =E6/G6 -> 0.33669676 | K6: =RANK(G6,$G$5:$G$28) -> 19 | L6: =RANK(H6,$H$5:$H$28) -> 5
A7: Baseline | B7: HEED (fairness) | C7: Edited + variant | D7: + rotation-fairness penalty | E7: 743 | F7: 1154 | G7: 1960 | H7: 0.9974 | I7: =G7/$G$5-1 -> 0.064060803 | J7: =E7/G7 -> 0.37908163 | K7: =RANK(G7,$G$5:$G$28) -> 18 | L7: =RANK(H7,$H$5:$H$28) -> 3
A8: Baseline | B8: PEGASIS | C8: Edited | D8: Greedy chain, rotating leader | E8: 1324 | F8: 2352 | G8: 3504 | H8: 0.9942 | I8: =G8/$G$5-1 -> 0.90228013 | J8: =E8/G8 -> 0.37785388 | K8: =RANK(G8,$G$5:$G$28) -> 2 | L8: =RANK(H8,$H$5:$H$28) -> 6
A9: Literature hybrid | B9: SH-LEACH | C9: Edited | D9: LEACH + HEED, single doubling | E9: 1440 | F9: 1584 | G9: 1604 | H9: 0.9917 | I9: =G9/$G$5-1 -> -0.12920738 | J9: =E9/G9 -> 0.89775561 | K9: =RANK(G9,$G$5:$G$28) -> 22 | L9: =RANK(H9,$H$5:$H$28) -> 10
A10: Literature hybrid | B10: SH-LEACH | C10: Improved | D10: True iterative doubling, Cprob 0.10→0.03 | E10: 1247 | F10: 1600 | G10: 1649 | H10: 0.9979 | I10: =G10/$G$5-1 -> -0.10477742 | J10: =E10/G10 -> 0.75621589 | K10: =RANK(G10,$G$5:$G$28) -> 21 | L10: =RANK(H10,$H$5:$H$28) -> 1
A11: Literature hybrid | B11: H-LEACH | C11: Edited | D11: Energy gate 1.0× average | E11: 2177 | F11: 2255 | G11: 2305 | H11: 0.9733 | I11: =G11/$G$5-1 -> 0.25135722 | J11: =E11/G11 -> 0.94446855 | K11: =RANK(G11,$G$5:$G$28) -> 10 | L11: =RANK(H11,$H$5:$H$28) -> 18
A12: Literature hybrid | B12: H-LEACH | C12: Improved | D12: Energy gate relaxed to 0.8× | E12: 2347 | F12: 2449 | G12: 2499 | H12: 0.9733 | I12: =G12/$G$5-1 -> 0.35667752 | J12: =E12/G12 -> 0.93917567 | K12: =RANK(G12,$G$5:$G$28) -> 8 | L12: =RANK(H12,$H$5:$H$28) -> 18
A13: Context | B13: EECH-HEED | C13: Edited | D13: HEED + EECH (not LEACH+HEED) | E13: 1653 | F13: 2134 | G13: 2184 | H13: 0.9168 | I13: =G13/$G$5-1 -> 0.18566775 | J13: =E13/G13 -> 0.75686813 | K13: =RANK(G13,$G$5:$G$28) -> 13 | L13: =RANK(H13,$H$5:$H$28) -> 24
A14: Context | B14: EECH-HEED | C14: Improved | D14: + adaptive threshold-based sensing (transmits less) | E14: 2502 | F14: 3758 | G14: 3808 | H14: 0.9214 | I14: =G14/$G$5-1 -> 1.0673181 | J14: =E14/G14 -> 0.65703782 | K14: =RANK(G14,$G$5:$G$28) -> 1 | L14: =RANK(H14,$H$5:$H$28) -> 23
A15: Proposed | B15: v1 | C15: Proposed | D15: HEED-style CH selection + LEACH clustering, no reuse | E15: 330 | F15: 557 | G15: 1318 | H15: 0.9974 | I15: =G15/$G$5-1 -> -0.2844734 | J15: =E15/G15 -> 0.25037936 | K15: =RANK(G15,$G$5:$G$28) -> 24 | L15: =RANK(H15,$H$5:$H$28) -> 3
A16: Proposed | B16: v2 | C16: Proposed | D16: + rotation-fairness penalty | E16: 345 | F16: 534 | G16: 1393 | H16: 0.9979 | I16: =G16/$G$5-1 -> -0.24375679 | J16: =E16/G16 -> 0.24766691 | K16: =RANK(G16,$G$5:$G$28) -> 23 | L16: =RANK(H16,$H$5:$H$28) -> 1
... A28: Proposed | B28: v8-Chain (Center) | C28: Proposed | D28: v8 + energy-aware CH relay (0 relays) | E28: 2621 | F28: 2711 | G28: 2756 | H28: 0.992668 | I28: =G28/$G$5-1 -> 0.49619978 | J28: =E28/G28 -> 0.95101597 | K28: =RANK(G28,$G$5:$G$28) -> 5 | L28: =RANK(H28,$H$5:$H$28) -> 8
A30: LND vs LEACH uses LEACH (Edited) as the reference. FND ÷ LND close to 1 means nodes die close together (balanced load). v5b LND is inflated by stranded, silent nodes (its last 1038 rounds delivered 59 packets).

Sheet Reproduction
A1: Published results vs. our reproductions
A2: Published = as reported in each original paper (different settings per paper). Paper-exact = our code in the paper's own settings. Unified = our code in the common environment.
A4: Protocol | B4: Published FND | C4: Published LND | D4: Paper-exact FND | E4: Paper-exact HND | F4: Paper-exact LND | G4: Paper-exact PDR | H4: Unified FND | I4: Unified HND | J4: Unified LND | K4: Unified PDR | L4: Paper-exact vs Published (LND) | M4: Unified vs Paper-exact (LND) | N4: Paper-exact settings | O4: Published source
A5: LEACH | B5: 932 | C5: 1312 | D5: 1035 | E5: 1152 | F5: 1327 | G5: 0.9862 | H5: 1383 | I5: 1586 | J5: 1842 | K5: 0.994 | L5: =IF(ISNUMBER(C5),F5/C5-1,"n/a") -> 0.011432927 | M5: =J5/F5-1 -> 0.38809344 | N5: 50×50 m, far BS, single-term radio, setup cost not charged (as in paper) | O5: Heinzelman et al., 2000 — Table 2 (0.5 J)
A6: HEED | B6: n/a | C6: graph only | D6: 734 | E6: 1384 | F6: 2259 | G6: 0.998 | H6: 634 | I6: 1216 | J6: 1883 | K6: 0.9968 | L6: =IF(ISNUMBER(C6),F6/C6-1,"n/a") -> n/a | M6: =J6/F6-1 -> -0.16644533 | N6: N = 500, sink (50,175), E0 = 2 J, 125-byte packet, 5 frames/round | O6: Younis & Fahmy, 2004 — graph only (Fig. 8a/8b)
A7: PEGASIS | B7: 1578 | C7: 2192 | D7: 1616 | E7: 2017 | F7: 2186 | G7: 0.9886 | H7: 1324 | I7: 2352 | J7: 3504 | K7: 0.9942 | L7: =IF(ISNUMBER(C7),F7/C7-1,"n/a") -> -0.0027372263 | M7: =J7/F7-1 -> 0.60292772 | N7: 50×50 m, far BS, single-term radio | O7: Lindsey & Raghavendra, 2002 — Table 1 (50×50 m)
A8: SH-LEACH | B8: n/a | C8: graph only | D8: 493 | E8: 747 | F8: 884 | G8: 0.9953 | H8: 1440 | I8: 1584 | J8: 1604 | K8: 0.9917 | L8: =IF(ISNUMBER(C8),F8/C8-1,"n/a") -> n/a | M8: =J8/F8-1 -> 0.81447964 | N8: N = 100, Cprob = 0.10 | O8: Shrestha et al., 2015 — graph only (Fig. 2)
A9: H-LEACH | B9: n/a | C9: 4312 | D9: 1080 | E9: 1160 | F9: 1210 | G9: 0.9475 | H9: 2177 | I9: 2255 | J9: 2305 | K9: 0.9733 | L9: =IF(ISNUMBER(C9),F9/C9-1,"n/a") -> -0.71938776 | M9: =J9/F9-1 -> 0.90495868 | N9: With required fallback (literal gate deadlocks) | O9: Razaque et al., 2016 — ≈ read from Fig. 2
A10: EECH-HEED | B10: 1250 | C10: 2200 | D10: 792 | E10: 1079 | F10: 1129 | G10: 0.9043 | H10: 1653 | I10: 2134 | J10: 2184 | K10: 0.9168 | L10: =IF(ISNUMBER(C10),F10/C10-1,"n/a") -> -0.48681818 | M10: =J10/F10-1 -> 0.93445527 | N10: 4000-bit packet | O10: Kaur, Kour & Singh, 2025 — Table 7
A12: H-LEACH published LND is read from the paper's Fig. 2 (≈4312). The unified environment differs in field size, BS position, radio model, packet size and initial energy, so the Unified column is the only fair basis for comparing protocols with each other.

Sheet Proposed Evolution
A1: Proposed protocol — version-by-version evolution
A2: Each version changes one mechanism. Δ columns are formulas: vs. the previous row and vs. v1.
A4: Version | B4: BS | C4: Setup interval | D4: Change introduced | E4: FND | F4: HND | G4: LND | H4: PDR | I4: Δ FND vs prev | J4: Δ LND vs prev | K4: Δ PDR vs prev | L4: Δ LND vs v1
A5: v1 | B5: Center | C5: 5 | D5: HEED-style CH selection + LEACH clustering, no reuse | E5: 330 | F5: 557 | G5: 1318 | H5: 0.9974 | I5: — | J5: — | K5: — | L5: =G5/$G$5-1 -> 0
A6: v2 | B6: Center | C6: 5 | D6: + rotation-fairness penalty | E6: 345 | F6: 534 | G6: 1393 | H6: 0.9979 | I6: =E6/E5-1 -> 0.045454545 | J6: =G6/G5-1 -> 0.056904401 | K6: =(H6-H5)*100 -> 0.05 | L6: =G6/$G$5-1 -> 0.056904401
A7: v3 | B7: Center | C7: 5 | D7: Single-pass energy × connectivity score + 5-round reuse | E7: 1730 | F7: 2081 | G7: 2703 | H7: 0.9772 | I7: =E7/E6-1 -> 4.0144928 | J7: =G7/G6-1 -> 0.94041637 | K7: =(H7-H6)*100 -> -2.07 | L7: =G7/$G$5-1 -> 1.0508346
A8: v4 | B8: Center | C8: 15 | D8: Setup interval 5 → 15 rounds | E8: 1513 | F8: 2219 | G8: 2521 | H8: 0.9467 | I8: =E8/E7-1 -> -0.12543353 | J8: =G8/G7-1 -> -0.067332593 | K8: =(H8-H7)*100 -> -3.05 | L8: =G8/$G$5-1 -> 0.91274659
A9: v5 | B9: Center | C9: 15 | D9: + Backup CH failover | E9: 1513 | F9: 2127 | G9: 2416 | H9: 0.9705 | I9: =E9/E8-1 -> 0 | J9: =G9/G8-1 -> -0.041650139 | K9: =(H9-H8)*100 -> 2.38 | L9: =G9/$G$5-1 -> 0.83308042
A10: v5-exp (Int 5) | B10: Center | C10: 5 | D10: Interval 5 + Backup + Cluster Repair | E10: 1730 | F10: 2086 | G10: 2156 | H10: 0.9827 | I10: =E10/E9-1 -> 0.14342366 | J10: =G10/G9-1 -> -0.10761589 | K10: =(H10-H9)*100 -> 1.22 | L10: =G10/$G$5-1 -> 0.63581184
A11: v5-exp (Int 10) | B11: Center | C11: 10 | D11: Interval 10 + Backup + Cluster Repair | E11: 1621 | F11: 2141 | G11: 2291 | H11: 0.9794 | I11: =E11/E10-1 -> -0.06300578 | J11: =G11/G10-1 -> 0.062615955 | K11: =(H11-H10)*100 -> -0.33 | L11: =G11/$G$5-1 -> 0.73823976
A12: v6 (Center) | B12: Center | C12: 5 | D12: CH-to-CH ordered chain | E12: 1551 | F12: 1981 | G12: 2106 | H12: 0.97494 | I12: =E12/E11-1 -> -0.04318322 | J12: =G12/G11-1 -> -0.080750764 | K12: =(H12-H11)*100 -> -0.446 | L12: =G12/$G$5-1 -> 0.59787557
A13: v7 (Center) | B13: Center | C13: 5 | D13: Chain + Backup + Chain Repair | E13: 1551 | F13: 1976 | G13: 2066 | H13: 0.98432 | I13: =E13/E12-1 -> 0 | J13: =G13/G12-1 -> -0.018993352 | K13: =(H13-H12)*100 -> 0.938 | L13: =G13/$G$5-1 -> 0.56752656
A14: v6 (Far BS) | B14: Far | C14: 5 | D14: CH-to-CH ordered chain | E14: 1266 | F14: 1910 | G14: 2031 | H14: 0.97075 | I14: =E14/E13-1 -> -0.18375242 | J14: =G14/G13-1 -> -0.016940949 | K14: =(H14-H13)*100 -> -1.357 | L14: =G14/$G$5-1 -> 0.54097117
A15: v7 (Far BS) | B15: Far | C15: 5 | D15: Chain + Backup + Chain Repair | E15: 1266 | F15: 1891 | G15: 1976 | H15: 0.98135 | I15: =E15/E14-1 -> 0 | J15: =G15/G14-1 -> -0.027080256 | K15: =(H15-H14)*100 -> 1.06 | L15: =G15/$G$5-1 -> 0.49924127
A16: v7.1 Multihop (Int 5) | B16: Center | C16: 5 | D16: Greedy multihop tree + Backup + Routing Repair | E16: 1491 | F16: 1991 | G16: 2086 | H16: 0.9849 | I16: =E16/E15-1 -> 0.17772512 | J16: =G16/G15-1 -> 0.055668016 | K16: =(H16-H15)*100 -> 0.355 | L16: =G16/$G$5-1 -> 0.58270106
A17: v7.2 Multihop (Int 10) | B17: Center | C17: 10 | D17: Same multihop, interval 10 | E17: 1381 | F17: 2071 | G17: 2241 | H17: 0.97878 | I17: =E17/E16-1 -> -0.073775989 | J17: =G17/G16-1 -> 0.07430489 | K17: =(H17-H16)*100 -> -0.612 | L17: =G17/$G$5-1 -> 0.70030349
... A22: v8-Chain (Far BS) | B22: Far | C22: 5 | D22: v8 + energy-aware CH relay (4,710 relays) | E22: 1716 | F22: 1886 | G22: 1956 | H22: 0.990719 | I22: =E22/E21-1 -> -0.34528806 | J22: =G22/G21-1 -> -0.29027576 | K22: =(H22-H21)*100 -> -0.1949 | L22: =G22/$G$5-1 -> 0.48406677
A24: Rows are in the order they were developed. Center and Far-BS variants of v6/v7/v8 are controlled pairs (only the BS position differs): compare them on the "Center vs Far BS" sheet, not row-to-row here.
A26: Chart data (center-BS versions, formulas)
A27: Version | B27: FND | C27: HND | D27: LND | E27: PDR
A28: =A5 -> v1 | B28: =E5 -> 330 | C28: =F5 -> 557 | D28: =G5 -> 1318 | E28: =H5 -> 0.9974
A29: =A6 -> v2 | B29: =E6 -> 345 | C29: =F6 -> 534 | D29: =G6 -> 1393 | E29: =H6 -> 0.9979
A30: =A7 -> v3 | B30: =E7 -> 1730 | C30: =F7 -> 2081 | D30: =G7 -> 2703 | E30: =H7 -> 0.9772
A31: =A8 -> v4 | B31: =E8 -> 1513 | C31: =F8 -> 2219 | D31: =G8 -> 2521 | E31: =H8 -> 0.9467
A32: =A9 -> v5 | B32: =E9 -> 1513 | C32: =F9 -> 2127 | D32: =G9 -> 2416 | E32: =H9 -> 0.9705
A33: =A10 -> v5-exp (Int 5) | B33: =E10 -> 1730 | C33: =F10 -> 2086 | D33: =G10 -> 2156 | E33: =H10 -> 0.9827
A34: =A11 -> v5-exp (Int 10) | B34: =E11 -> 1621 | C34: =F11 -> 2141 | D34: =G11 -> 2291 | E34: =H11 -> 0.9794
A35: =A12 -> v6 (Center) | B35: =E12 -> 1551 | C35: =F12 -> 1981 | D35: =G12 -> 2106 | E35: =H12 -> 0.97494
A36: =A13 -> v7 (Center) | B36: =E13 -> 1551 | C36: =F13 -> 1976 | D36: =G13 -> 2066 | E36: =H13 -> 0.98432
A37: =A16 -> v7.1 Multihop (Int 5) | B37: =E16 -> 1491 | C37: =F16 -> 1991 | D37: =G16 -> 2086 | E37: =H16 -> 0.9849
A38: =A17 -> v7.2 Multihop (Int 10) | B38: =E17 -> 1381 | C38: =F17 -> 2071 | D38: =G17 -> 2241 | E38: =H17 -> 0.97878
A39: =A18 -> v5b (Energy-Aware) | B39: =E18 -> 1730 | C39: =F18 -> 2091 | D39: =G18 -> 3203 | E39: =H18 -> 0.973087
A40: =A19 -> v8 (Center) | B40: =E19 -> 2621 | C40: =F19 -> 2711 | D40: =G19 -> 2761 | E40: =H19 -> 0.992224
A41: =A21 -> v8-Chain (Center) | B41: =E21 -> 2621 | C41: =F21 -> 2711 | D41: =G21 -> 2756 | E41: =H21 -> 0.992668

Sheet Center vs Far BS
A1: Controlled BS-placement pairs
A2: Same code and seed; only the BS position changes: center (50,50) vs far (50,−100). Δ = Far vs Center (formulas).
A4: Protocol | B4: FND Center | C4: HND Center | D4: LND Center | E4: PDR Center | F4: FND Far | G4: HND Far | H4: LND Far | I4: PDR Far | J4: Δ FND | K4: Δ LND | L4: Δ PDR
A5: v5b (Energy-Aware) | B5: 1730 | C5: 2091 | D5: 3203 | E5: 0.973087 | F5: 1055 | G5: 1616 | H5: 1861 | I5: 0.982785 | J5: =F5/B5-1 -> -0.39017341 | K5: =H5/D5-1 -> -0.4189822 | L5: =(I5-E5)*100 -> 0.9698
A6: v6 (ordered chain) | B6: 1551 | C6: 1981 | D6: 2106 | E6: 0.97494 | F6: 1266 | G6: 1910 | H6: 2031 | I6: 0.97075 | J6: =F6/B6-1 -> -0.18375242 | K6: =H6/D6-1 -> -0.035612536 | L6: =(I6-E6)*100 -> -0.419
A7: v7 (chain + backup + repair) | B7: 1551 | C7: 1976 | D7: 2066 | E7: 0.98432 | F7: 1266 | G7: 1891 | H7: 1976 | I7: 0.98135 | J7: =F7/B7-1 -> -0.18375242 | K7: =H7/D7-1 -> -0.043562439 | L7: =(I7-E7)*100 -> -0.297
A8: v8 | B8: 2621 | C8: 2711 | D8: 2761 | E8: 0.992224 | F8: 1471 | G8: 1646 | H8: 1716 | I8: 0.986599 | J8: =F8/B8-1 -> -0.43876383 | K8: =H8/D8-1 -> -0.37848606 | L8: =(I8-E8)*100 -> -0.5625
A9: v8-Chain (energy-aware relay) | B9: 2621 | C9: 2711 | D9: 2756 | E9: 0.992668 | F9: 1716 | G9: 1886 | H9: 1956 | I9: 0.990719 | J9: =F9/B9-1 -> -0.34528806 | K9: =H9/D9-1 -> -0.29027576 | L9: =(I9-E9)*100 -> -0.1949

Sheet v8 Analysis
A1: v8 / v8-Chain — ablation, routing and robustness
A2: A. Each ablation row disables ONE mechanism. B. CH routing mode. C. Mean of 8 random topologies.
A4: A. Leave-one-out ablation (BS center, seed 12345)
A5: Variant | B5: Mechanism removed | C5: FND | D5: HND | E5: LND | F5: PDR | G5: Delivered packets | H5: Δ FND vs full | I5: Δ Delivered vs full
A6: v8 (full) | B6: — | C6: 2621 | D6: 2711 | E6: 2761 | F6: 0.992224 | G6: 268610 | H6: =C6/$C$6-1 -> 0 | I6: =G6/$G$6-1 -> 0
A7: v8 − I1 | B7: Epoch-exhaustion fix | C7: 2621 | D7: 2711 | E7: 2761 | F7: 0.992224 | G7: 268610 | H7: =C7/$C$6-1 -> 0 | I7: =G7/$G$6-1 -> 0
A8: v8 − I2 | B8: Proactive CH handover | C8: 2585 | D8: 2726 | E8: 2766 | F8: 0.989804 | G8: 268509 | H8: =C8/$C$6-1 -> -0.013735216 | I8: =G8/$G$6-1 -> -0.00037600983
A9: v8 − I3 | B9: Orphan re-join | C9: 2621 | D9: 2711 | E9: 2761 | F9: 0.992224 | G9: 268610 | H9: =C9/$C$6-1 -> 0 | I9: =G9/$G$6-1 -> 0
A10: v8 − I4 | B10: Direct-to-BS | C10: 1821 | D10: 2001 | E10: 2076 | F10: 0.993171 | G10: 198218 | H10: =C10/$C$6-1 -> -0.30522701 | I10: =G10/$G$6-1 -> -0.26206024
A11: v8 − I5 | B11: Energy-gated CH election | C11: 2171 | D11: 2641 | E11: 2746 | F11: 0.990522 | G11: 258228 | H11: =C11/$C$6-1 -> -0.17169019 | I11: =G11/$G$6-1 -> -0.038650832
A12: Threshold fix only | B12: All of I1–I5 | C12: 1730 | D12: 2086 | E12: 2166 | F12: 0.98163 | G12: 201565 | H12: =C12/$C$6-1 -> -0.33994659 | I12: =G12/$G$6-1 -> -0.24959979
A15: B. CH routing mode (seed 12345 and 8-seed mean)
A16: Routing mode | B16: BS | C16: FND | D16: HND | E16: LND | F16: PDR | G16: Mean FND | H16: Mean HND | I16: Mean LND | J16: Mean PDR
A17: Direct CH→BS (v8) | B17: Center | C17: 2621 | D17: 2711 | E17: 2761 | F17: 0.992224 | G17: 2618 | H17: 2720 | I17: 2766 | J17: 0.9926
A18: Ordered chain | B18: Center | C18: 2566 | D18: 2661 | E18: 2692 | F18: 0.991087 | G18: 2571 | H18: 2664 | I18: 2704 | J18: 0.9922
A19: Energy-aware relay (v8-Chain) | B19: Center | C19: 2621 | D19: 2711 | E19: 2756 | F19: 0.992668 | G19: 2618 | H19: 2720 | I19: 2765 | J19: 0.9925
A20: Direct CH→BS (v8) | B20: Far | C20: 1471 | D20: 1646 | E20: 1716 | F20: 0.986599 | G20: 1487 | H20: 1673 | I20: 1730 | J20: 0.9886
A21: Ordered chain | B21: Far | C21: 1696 | D21: 1901 | E21: 1961 | F21: 0.990255 | G21: 1740 | H21: 1932 | I21: 1992 | J21: 0.9907
A22: Energy-aware relay (v8-Chain) | B22: Far | C22: 1716 | D22: 1886 | E22: 1956 | F22: 0.990719 | G22: 1743 | H22: 1932 | I22: 1995 | J22: 0.9905
A25: C. Robustness — mean of 8 topologies (seeds 12345, 1, 7, 42, 99, 2024, 31337, 555)
A26: Protocol | B26: BS | C26: Mean FND | D26: Mean HND | E26: Mean LND | F26: Mean PDR
A27: v5b | B27: Center | C27: 1688 | D27: 2119 | E27: 2374 | F27: 0.9756
A28: v8 | B28: Center | C28: 2618 | D28: 2720 | E28: 2766 | F28: 0.9926
A29: v5b | B29: Far | C29: 1152 | D29: 1674 | E29: 2001 | F29: 0.9772
A30: v8 | B30: Far | C30: 1487 | D30: 1673 | E30: 1732 | F30: 0.9882
A32: Reading: direct-to-BS (I4) and the energy gate (I5) carry most of the v8 lifetime gain; I1 and I3 are safety nets with no effect in the full combination for this seed. The energy-aware relay never fires at the center BS and forms a chain on its own at the far BS.
